<mujocoinclude>
        <!-- Summit XL Steel Mobile Base -->
        <body name="base_footprint" pos="0 0 0">

            <!-- BASE_LINK -->
            <body name="base" pos="0 0 0.127">
                <inertial pos="0 0 0" quat="1 0 0 0" mass="125.0" diaginertia="1.391 6.853 6.125" />
                <geom type="mesh" rgba="0 0 0 1" mesh="summit_xls_chassis" contype="0" conaffinity="0" group="1"/>
                <geom type="box" size="0.35 0.3 0.01" pos="0.0 0 0.148566" quat="1 0 0 0" rgba="0 1 0 0" contype="1" conaffinity="1"/>

                <!-- CHAPAS INOX TAPAS -->
                <!-- 0.266434 -->
                <geom type="mesh" pos="0.0 0 0.155" quat="1 0 0 0" rgba="0.5 0.5 0.5 1" mesh="summit_xls_chapas_inox_tapas" contype="0" conaffinity="0" group="2"/>

                <!-- LOGO ROBOTNIK IZQUIERDO -->
                <!-- <geom type="mesh" pos="0.0 0.28931 0.203434" quat="1 0 0 0" rgba="0.5 0.5 0.5 1" mesh="robotnik_logo_chasis" contype="0" conaffinity="0" group="2"/> -->

                <!-- LOGO ROBOTNIK DERECHO -->
                <!-- <geom type="mesh" pos="0.0 -0.28931 0.203434" quat="0 0 0 1" rgba="0.5 0.5 0.5 1" mesh="robotnik_logo_chasis" contype="0" conaffinity="0" group="2"/> -->

                <!-- LOGO ROBOTNIK FRONTAL -->
                <!-- <geom type="mesh" pos="0.345 0.0 0.0" quat="-0.7071068 0 0 0.7071068" rgba="0.5 0.5 0.5 1" mesh="robotnik_logo_chasis" contype="0" conaffinity="0" group="2"/> -->

                <!-- LOGO ROBOTNIK TRASERO -->
                <!-- <geom type="mesh" pos="-0.345 0.0 0.0" quat="0.7071068 0 0 0.7071068" rgba="0.5 0.5 0.5 1" mesh="robotnik_logo_chasis" contype="0" conaffinity="0" group="2"/> -->

                <!-- Wheels -->
                <body name="front_right_wheel_intermediate_link" pos="0.2225 -0.2045 0">
                    <inertial pos="0 0 0" quat="0.707107 0 0 0.707107" mass="6.5" diaginertia="0.0524193 0.0303095 0.0303095" />
                    <joint name="front_right_wheel_rolling_joint" pos="0 0 0" axis="0 1 0" />
                    <geom size="0.120 0.0435" quat="0.707107 0.707107 0 0" type="cylinder" rgba="0.2 0.2 0.2 0.5" contype="1" conaffinity="0" group="3" />
                    <geom type="mesh" mesh="summit_xls_omni_wheel_2" contype="0" conaffinity="0" group="2" rgba="0.2 0.2 0.2 1"/>


                    <body name="front_right_roller_0_link" pos="0.04385159698893431 0.0 0.011749999999999998">
                        <joint name="front_right_slipping_0_joint" type="hinge" pos="0 0 0" axis="-0.006296806022131382 0.0435 0.023499999999999997" damping="0.1" limited="false" actuatorfrclimited="false"/>
                        <inertial pos="0 0 0" quat="0.711549 0.711549 0 0 " mass="0.001" diaginertia="0.00001 0.00001 0.00001" />
                        <geom size="0.08" quat="1 0 0 0" type="sphere" rgba="0.2 0.2 0.2 1" contype="1" conaffinity="0" group="3"/>
                    </body>

                    <body name="front_right_roller_1_link" pos="0.03210159698893431 0.0 0.032101596988934306">
                        <joint name="front_right_slipping_1_joint" type="hinge" pos="0 0 0" axis="-0.01720319397786861 0.0435 0.017203193977868615" damping="0.1" limited="false" actuatorfrclimited="false"/>
                        <inertial pos="0 0 0" quat="0.711549 0.711549 0 0 " mass="0.001" diaginertia="0.00001 0.00001 0.00001" />
                        <geom size="0.08" quat="1 0 0 0" type="sphere" rgba="0.2 0.2 0.2 1" contype="1" conaffinity="0" group="3"/>
                    </body>

                    <body name="front_right_roller_2_link" pos="0.011750000000000005 0.0 0.0438515969889343">
                        <joint name="front_right_slipping_2_joint" type="hinge" pos="0 0 0" axis="-0.023500000000000004 0.0435 0.006296806022131389" damping="0.1" limited="false" actuatorfrclimited="false"/>
                        <inertial pos="0 0 0" quat="0.711549 0.711549 0 0 " mass="0.001" diaginertia="0.00001 0.00001 0.00001" />
                        <geom size="0.08" quat="1 0 0 0" type="sphere" rgba="0.2 0.2 0.2 1" contype="1" conaffinity="0" group="3"/>
                    </body>

                    <body name="front_right_roller_3_link" pos="-0.011749999999999993 0.0 0.04385159698893431">
                        <joint name="front_right_slipping_3_joint" type="hinge" pos="0 0 0" axis="-0.023499999999999993 0.0435 -0.006296806022131382" damping="0.1" limited="false" actuatorfrclimited="false"/>
                        <inertial pos="0 0 0" quat="0.711549 0.711549 0 0 " mass="0.001" diaginertia="0.00001 0.00001 0.00001" />
                        <geom size="0.08" quat="1 0 0 0" type="sphere" rgba="0.2 0.2 0.2 1" contype="1" conaffinity="0" group="3"/>
                    </body>

                    <body name="front_right_roller_4_link" pos="-0.0321015969889343 0.0 0.03210159698893432">
                        <joint name="front_right_slipping_4_joint" type="hinge" pos="0 0 0" axis="-0.01720319397786862 0.0435 -0.0172031939778686" damping="0.1" limited="false" actuatorfrclimited="false"/>
                        <inertial pos="0 0 0" quat="0.711549 0.711549 0 0 " mass="0.001" diaginertia="0.00001 0.00001 0.00001" />
                        <geom size="0.08" quat="1 0 0 0" type="sphere" rgba="0.2 0.2 0.2 1" contype="1" conaffinity="0" group="3"/>
                    </body>

                    <body name="front_right_roller_5_link" pos="-0.0438515969889343 0.0 0.011750000000000012">
                        <joint name="front_right_slipping_5_joint" type="hinge" pos="0 0 0" axis="-0.006296806022131389 0.0435 -0.02350000000000001" damping="0.1" limited="false" actuatorfrclimited="false"/>
                        <inertial pos="0 0 0" quat="0.711549 0.711549 0 0 " mass="0.001" diaginertia="0.00001 0.00001 0.00001" />
                        <geom size="0.08" quat="1 0 0 0" type="sphere" rgba="0.2 0.2 0.2 1" contype="1" conaffinity="0" group="3"/>
                    </body>

                    <body name="front_right_roller_6_link" pos="-0.043851596988934316 0.0 -0.011749999999999991">
                        <joint name="front_right_slipping_6_joint" type="hinge" pos="0 0 0" axis="0.006296806022131375 0.0435 -0.023499999999999993" damping="0.1" limited="false" actuatorfrclimited="false"/>
                        <inertial pos="0 0 0" quat="0.711549 0.711549 0 0 " mass="0.001" diaginertia="0.00001 0.00001 0.00001" />
                        <geom size="0.08" quat="1 0 0 0" type="sphere" rgba="0.2 0.2 0.2 1" contype="1" conaffinity="0" group="3"/>
                    </body>

                    <body name="front_right_roller_7_link" pos="-0.03210159698893432 0.0 -0.03210159698893429">
                        <joint name="front_right_slipping_7_joint" type="hinge" pos="0 0 0" axis="0.017203193977868604 0.0435 -0.017203193977868618" damping="0.1" limited="false" actuatorfrclimited="false"/>
                        <inertial pos="0 0 0" quat="0.711549 0.711549 0 0 " mass="0.001" diaginertia="0.00001 0.00001 0.00001" />
                        <geom size="0.08" quat="1 0 0 0" type="sphere" rgba="0.2 0.2 0.2 1" contype="1" conaffinity="0" group="3"/>
                    </body>

                    <body name="front_right_roller_8_link" pos="-0.011750000000000014 0.0 -0.0438515969889343">
                        <joint name="front_right_slipping_8_joint" type="hinge" pos="0 0 0" axis="0.023500000000000014 0.0435 -0.006296806022131396" damping="0.1" limited="false" actuatorfrclimited="false"/>
                        <inertial pos="0 0 0" quat="0.711549 0.711549 0 0 " mass="0.001" diaginertia="0.00001 0.00001 0.00001" />
                        <geom size="0.08" quat="1 0 0 0" type="sphere" rgba="0.2 0.2 0.2 1" contype="1" conaffinity="0" group="3"/>
                    </body>

                    <body name="front_right_roller_9_link" pos="0.01174999999999998 0.0 -0.043851596988934316">
                        <joint name="front_right_slipping_9_joint" type="hinge" pos="0 0 0" axis="0.023499999999999976 0.0435 0.006296806022131368" damping="0.1" limited="false" actuatorfrclimited="false"/>
                        <inertial pos="0 0 0" quat="0.711549 0.711549 0 0 " mass="0.001" diaginertia="0.00001 0.00001 0.00001" />
                        <geom size="0.08" quat="1 0 0 0" type="sphere" rgba="0.2 0.2 0.2 1" contype="1" conaffinity="0" group="3"/>
                    </body>

                    <body name="front_right_roller_10_link" pos="0.032101596988934285 0.0 -0.032101596988934326">
                        <joint name="front_right_slipping_10_joint" type="hinge" pos="0 0 0" axis="0.017203193977868635 0.0435 0.01720319397786861" damping="0.1" limited="false" actuatorfrclimited="false"/>
                        <inertial pos="0 0 0" quat="0.711549 0.711549 0 0 " mass="0.001" diaginertia="0.00001 0.00001 0.00001" />
                        <geom size="0.08" quat="1 0 0 0" type="sphere" rgba="0.2 0.2 0.2 1" contype="1" conaffinity="0" group="3"/>
                    </body>

                    <body name="front_right_roller_11_link" pos="0.0438515969889343 0.0 -0.01175000000000001">
                        <joint name="front_right_slipping_11_joint" type="hinge" pos="0 0 0" axis="0.006296806022131396 0.0435 0.02350000000000002" damping="0.1" limited="false" actuatorfrclimited="false"/>
                        <inertial pos="0 0 0" quat="0.711549 0.711549 0 0 " mass="0.001" diaginertia="0.00001 0.00001 0.00001" />
                        <geom size="0.08" quat="1 0 0 0" type="sphere" rgba="0.2 0.2 0.2 1" contype="1" conaffinity="0" group="3"/>
                    </body>
                </body>

                <body name="front_left_wheel_intermediate_link" pos="0.2225 0.2045 0">
                    <inertial pos="0 0 0" quat="0.707107 0 0 0.707107" mass="6.5" diaginertia="0.0524193 0.0303095 0.0303095" />
                    <joint name="front_left_wheel_rolling_joint" pos="0 0 0" axis="0 1 0" />
                    <geom size="0.120 0.0435" quat="0.707107 0.707107 0 0" type="cylinder" rgba="0.2 0.2 0.2 0.5" contype="1" conaffinity="0" group="3"/>
                    <geom type="mesh" mesh="summit_xls_omni_wheel_1" contype="0" conaffinity="0" group="2" rgba="0.2 0.2 0.2 1"/>


                    <body name="front_left_roller_0_link" pos="0.0438515969889343 0.0 -0.01175000000000001">
                        <joint name="front_left_slipping_0_joint" type="hinge" pos="0 0 0" axis="-0.006296806022131396 0.0435 -0.02350000000000002" damping="0.1" limited="false" actuatorfrclimited="false"/>
                        <inertial pos="0 0 0" quat="0.711549 0.711549 0 0 " mass="0.001" diaginertia="0.00001 0.00001 0.00001" />
                        <geom size="0.08" quat="1 0 0 0" type="sphere" rgba="0.2 0.2 0.2 1" contype="1" conaffinity="0" group="3"/>
                    </body>

                    <body name="front_left_roller_1_link" pos="0.04385159698893431 0.0 0.011749999999999998">
                        <joint name="front_left_slipping_1_joint" type="hinge" pos="0 0 0" axis="0.006296806022131382 0.0435 -0.023499999999999997" damping="0.1" limited="false" actuatorfrclimited="false"/>
                        <inertial pos="0 0 0" quat="0.711549 0.711549 0 0 " mass="0.001" diaginertia="0.00001 0.00001 0.00001" />
                        <geom size="0.08" quat="1 0 0 0" type="sphere" rgba="0.2 0.2 0.2 1" contype="1" conaffinity="0" group="3"/>
                    </body>

                    <body name="front_left_roller_2_link" pos="0.03210159698893431 0.0 0.032101596988934306">
                        <joint name="front_left_slipping_2_joint" type="hinge" pos="0 0 0" axis="0.01720319397786861 0.0435 -0.017203193977868615" damping="0.1" limited="false" actuatorfrclimited="false"/>
                        <inertial pos="0 0 0" quat="0.711549 0.711549 0 0 " mass="0.001" diaginertia="0.00001 0.00001 0.00001" />
                        <geom size="0.08" quat="1 0 0 0" type="sphere" rgba="0.2 0.2 0.2 1" contype="1" conaffinity="0" group="3"/>
                    </body>

                    <body name="front_left_roller_3_link" pos="0.011750000000000005 0.0 0.0438515969889343">
                        <joint name="front_left_slipping_3_joint" type="hinge" pos="0 0 0" axis="0.023500000000000004 0.0435 -0.006296806022131389" damping="0.1" limited="false" actuatorfrclimited="false"/>
                        <inertial pos="0 0 0" quat="0.711549 0.711549 0 0 " mass="0.001" diaginertia="0.00001 0.00001 0.00001" />
                        <geom size="0.08" quat="1 0 0 0" type="sphere" rgba="0.2 0.2 0.2 1" contype="1" conaffinity="0" group="3"/>
                    </body>

                    <body name="front_left_roller_4_link" pos="-0.011749999999999993 0.0 0.04385159698893431">
                        <joint name="front_left_slipping_4_joint" type="hinge" pos="0 0 0" axis="0.023499999999999993 0.0435 0.006296806022131382" damping="0.1" limited="false" actuatorfrclimited="false"/>
                        <inertial pos="0 0 0" quat="0.711549 0.711549 0 0 " mass="0.001" diaginertia="0.00001 0.00001 0.00001" />
                        <geom size="0.08" quat="1 0 0 0" type="sphere" rgba="0.2 0.2 0.2 1" contype="1" conaffinity="0" group="3"/>
                    </body>

                    <body name="front_left_roller_5_link" pos="-0.0321015969889343 0.0 0.03210159698893432">
                        <joint name="front_left_slipping_5_joint" type="hinge" pos="0 0 0" axis="0.01720319397786862 0.0435 0.0172031939778686" damping="0.1" limited="false" actuatorfrclimited="false"/>
                        <inertial pos="0 0 0" quat="0.711549 0.711549 0 0 " mass="0.001" diaginertia="0.00001 0.00001 0.00001" />
                        <geom size="0.08" quat="1 0 0 0" type="sphere" rgba="0.2 0.2 0.2 1" contype="1" conaffinity="0" group="3"/>
                    </body>

                    <body name="front_left_roller_6_link" pos="-0.0438515969889343 0.0 0.01175000000000001">
                        <joint name="front_left_slipping_6_joint" type="hinge" pos="0 0 0" axis="0.006296806022131389 0.0435 0.02350000000000001" damping="0.1" limited="false" actuatorfrclimited="false"/>
                        <inertial pos="0 0 0" quat="0.711549 0.711549 0 0 " mass="0.001" diaginertia="0.00001 0.00001 0.00001" />
                        <geom size="0.08" quat="1 0 0 0" type="sphere" rgba="0.2 0.2 0.2 1" contype="1" conaffinity="0" group="3"/>
                    </body>

                    <body name="front_left_roller_7_link" pos="-0.043851596988934316 0.0 -0.01174999999999999">
                        <joint name="front_left_slipping_7_joint" type="hinge" pos="0 0 0" axis="-0.006296806022131375 0.0435 0.023499999999999993" damping="0.1" limited="false" actuatorfrclimited="false"/>
                        <inertial pos="0 0 0" quat="0.711549 0.711549 0 0 " mass="0.001" diaginertia="0.00001 0.00001 0.00001" />
                        <geom size="0.08" quat="1 0 0 0" type="sphere" rgba="0.2 0.2 0.2 1" contype="1" conaffinity="0" group="3"/>
                    </body>

                    <body name="front_left_roller_8_link" pos="-0.03210159698893432 0.0 -0.03210159698893429">
                        <joint name="front_left_slipping_8_joint" type="hinge" pos="0 0 0" axis="-0.017203193977868604 0.0435 0.017203193977868618" damping="0.1" limited="false" actuatorfrclimited="false"/>
                        <inertial pos="0 0 0" quat="0.711549 0.711549 0 0 " mass="0.001" diaginertia="0.00001 0.00001 0.00001" />
                        <geom size="0.08" quat="1 0 0 0" type="sphere" rgba="0.2 0.2 0.2 1" contype="1" conaffinity="0" group="3"/>
                    </body>

                    <body name="front_left_roller_9_link" pos="-0.011750000000000016 0.0 -0.0438515969889343">
                        <joint name="front_left_slipping_9_joint" type="hinge" pos="0 0 0" axis="-0.023500000000000014 0.0435 0.006296806022131396" damping="0.1" limited="false" actuatorfrclimited="false"/>
                        <inertial pos="0 0 0" quat="0.711549 0.711549 0 0 " mass="0.001" diaginertia="0.00001 0.00001 0.00001" />
                        <geom size="0.08" quat="1 0 0 0" type="sphere" rgba="0.2 0.2 0.2 1" contype="1" conaffinity="0" group="3"/>
                    </body>

                    <body name="front_left_roller_10_link" pos="0.011749999999999981 0.0 -0.043851596988934316">
                        <joint name="front_left_slipping_10_joint" type="hinge" pos="0 0 0" axis="-0.023499999999999976 0.0435 -0.006296806022131368" damping="0.1" limited="false" actuatorfrclimited="false"/>
                        <inertial pos="0 0 0" quat="0.711549 0.711549 0 0 " mass="0.001" diaginertia="0.00001 0.00001 0.00001" />
                        <geom size="0.08" quat="1 0 0 0" type="sphere" rgba="0.2 0.2 0.2 1" contype="1" conaffinity="0" group="3"/>
                    </body>

                    <body name="front_left_roller_11_link" pos="0.032101596988934285 0.0 -0.032101596988934326">
                        <joint name="front_left_slipping_11_joint" type="hinge" pos="0 0 0" axis="-0.017203193977868635 0.0435 -0.01720319397786861" damping="0.1" limited="false" actuatorfrclimited="false"/>
                        <inertial pos="0 0 0" quat="0.711549 0.711549 0 0 " mass="0.001" diaginertia="0.00001 0.00001 0.00001" />
                        <geom size="0.08" quat="1 0 0 0" type="sphere" rgba="0.2 0.2 0.2 1" contype="1" conaffinity="0" group="3"/>
                    </body>
                </body>

                <body name="back_right_wheel_intermediate_link" pos="-0.2225 -0.2045 0">
                    <inertial pos="0 0 0" quat="0.707107 0 0 0.707107" mass="6.5" diaginertia="0.0524193 0.0303095 0.0303095" />
                    <joint name="back_right_wheel_rolling_joint" pos="0 0 0" axis="0 1 0" />
                    <geom size="0.120 0.0435" quat="0.707107 0.707107 0 0" type="cylinder" rgba="0.2 0.2 0.2 0.5" contype="1" conaffinity="0" group="3"/>
                    <geom type="mesh" mesh="summit_xls_omni_wheel_1" contype="0" conaffinity="0" group="2" rgba="0.2 0.2 0.2 1"/>


                    <body name="back_right_roller_0_link" pos="0.0438515969889343 0.0 -0.01175000000000001">
                        <joint name="back_right_slipping_0_joint" type="hinge" pos="0 0 0" axis="-0.006296806022131396 0.0435 -0.02350000000000002" damping="0.1" limited="false" actuatorfrclimited="false"/>
                        <inertial pos="0 0 0" quat="0.711549 0.711549 0 0 " mass="0.001" diaginertia="0.00001 0.00001 0.00001" />
                        <geom size="0.08" quat="1 0 0 0" type="sphere" rgba="0.2 0.2 0.2 1" contype="1" conaffinity="0" group="3"/>
                    </body>

                    <body name="back_right_roller_1_link" pos="0.04385159698893431 0.0 0.011749999999999998">
                        <joint name="back_right_slipping_1_joint" type="hinge" pos="0 0 0" axis="0.006296806022131382 0.0435 -0.023499999999999997" damping="0.1" limited="false" actuatorfrclimited="false"/>
                        <inertial pos="0 0 0" quat="0.711549 0.711549 0 0 " mass="0.001" diaginertia="0.00001 0.00001 0.00001" />
                        <geom size="0.08" quat="1 0 0 0" type="sphere" rgba="0.2 0.2 0.2 1" contype="1" conaffinity="0" group="3"/>
                    </body>

                    <body name="back_right_roller_2_link" pos="0.03210159698893431 0.0 0.032101596988934306">
                        <joint name="back_right_slipping_2_joint" type="hinge" pos="0 0 0" axis="0.01720319397786861 0.0435 -0.017203193977868615" damping="0.1" limited="false" actuatorfrclimited="false"/>
                        <inertial pos="0 0 0" quat="0.711549 0.711549 0 0 " mass="0.001" diaginertia="0.00001 0.00001 0.00001" />
                        <geom size="0.08" quat="1 0 0 0" type="sphere" rgba="0.2 0.2 0.2 1" contype="1" conaffinity="0" group="3"/>
                    </body>

                    <body name="back_right_roller_3_link" pos="0.011750000000000005 0.0 0.0438515969889343">
                        <joint name="back_right_slipping_3_joint" type="hinge" pos="0 0 0" axis="0.023500000000000004 0.0435 -0.006296806022131389" damping="0.1" limited="false" actuatorfrclimited="false"/>
                        <inertial pos="0 0 0" quat="0.711549 0.711549 0 0 " mass="0.001" diaginertia="0.00001 0.00001 0.00001" />
                        <geom size="0.08" quat="1 0 0 0" type="sphere" rgba="0.2 0.2 0.2 1" contype="1" conaffinity="0" group="3"/>
                    </body>

                    <body name="back_right_roller_4_link" pos="-0.011749999999999993 0.0 0.04385159698893431">
                        <joint name="back_right_slipping_4_joint" type="hinge" pos="0 0 0" axis="0.023499999999999993 0.0435 0.006296806022131382" damping="0.1" limited="false" actuatorfrclimited="false"/>
                        <inertial pos="0 0 0" quat="0.711549 0.711549 0 0 " mass="0.001" diaginertia="0.00001 0.00001 0.00001" />
                        <geom size="0.08" quat="1 0 0 0" type="sphere" rgba="0.2 0.2 0.2 1" contype="1" conaffinity="0" group="3"/>
                    </body>

                    <body name="back_right_roller_5_link" pos="-0.0321015969889343 0.0 0.03210159698893432">
                        <joint name="back_right_slipping_5_joint" type="hinge" pos="0 0 0" axis="0.01720319397786862 0.0435 0.0172031939778686" damping="0.1" limited="false" actuatorfrclimited="false"/>
                        <inertial pos="0 0 0" quat="0.711549 0.711549 0 0 " mass="0.001" diaginertia="0.00001 0.00001 0.00001" />
                        <geom size="0.08" quat="1 0 0 0" type="sphere" rgba="0.2 0.2 0.2 1" contype="1" conaffinity="0" group="3"/>
                    </body>

                    <body name="back_right_roller_6_link" pos="-0.0438515969889343 0.0 0.01175000000000001">
                        <joint name="back_right_slipping_6_joint" type="hinge" pos="0 0 0" axis="0.006296806022131389 0.0435 0.02350000000000001" damping="0.1" limited="false" actuatorfrclimited="false"/>
                        <inertial pos="0 0 0" quat="0.711549 0.711549 0 0 " mass="0.001" diaginertia="0.00001 0.00001 0.00001" />
                        <geom size="0.08" quat="1 0 0 0" type="sphere" rgba="0.2 0.2 0.2 1" contype="1" conaffinity="0" group="3"/>
                    </body>

                    <body name="back_right_roller_7_link" pos="-0.043851596988934316 0.0 -0.01174999999999999">
                        <joint name="back_right_slipping_7_joint" type="hinge" pos="0 0 0" axis="-0.006296806022131375 0.0435 0.023499999999999993" damping="0.1" limited="false" actuatorfrclimited="false"/>
                        <inertial pos="0 0 0" quat="0.711549 0.711549 0 0 " mass="0.001" diaginertia="0.00001 0.00001 0.00001" />
                        <geom size="0.08" quat="1 0 0 0" type="sphere" rgba="0.2 0.2 0.2 1" contype="1" conaffinity="0" group="3"/>
                    </body>

                    <body name="back_right_roller_8_link" pos="-0.03210159698893432 0.0 -0.03210159698893429">
                        <joint name="back_right_slipping_8_joint" type="hinge" pos="0 0 0" axis="-0.017203193977868604 0.0435 0.017203193977868618" damping="0.1" limited="false" actuatorfrclimited="false"/>
                        <inertial pos="0 0 0" quat="0.711549 0.711549 0 0 " mass="0.001" diaginertia="0.00001 0.00001 0.00001" />
                        <geom size="0.08" quat="1 0 0 0" type="sphere" rgba="0.2 0.2 0.2 1" contype="1" conaffinity="0" group="3"/>
                    </body>

                    <body name="back_right_roller_9_link" pos="-0.011750000000000016 0.0 -0.0438515969889343">
                        <joint name="back_right_slipping_9_joint" type="hinge" pos="0 0 0" axis="-0.023500000000000014 0.0435 0.006296806022131396" damping="0.1" limited="false" actuatorfrclimited="false"/>
                        <inertial pos="0 0 0" quat="0.711549 0.711549 0 0 " mass="0.001" diaginertia="0.00001 0.00001 0.00001" />
                        <geom size="0.08" quat="1 0 0 0" type="sphere" rgba="0.2 0.2 0.2 1" contype="1" conaffinity="0" group="3"/>
                    </body>

                    <body name="back_right_roller_10_link" pos="0.011749999999999981 0.0 -0.043851596988934316">
                        <joint name="back_right_slipping_10_joint" type="hinge" pos="0 0 0" axis="-0.023499999999999976 0.0435 -0.006296806022131368" damping="0.1" limited="false" actuatorfrclimited="false"/>
                        <inertial pos="0 0 0" quat="0.711549 0.711549 0 0 " mass="0.001" diaginertia="0.00001 0.00001 0.00001" />
                        <geom size="0.08" quat="1 0 0 0" type="sphere" rgba="0.2 0.2 0.2 1" contype="1" conaffinity="0" group="3"/>
                    </body>

                    <body name="back_right_roller_11_link" pos="0.032101596988934285 0.0 -0.032101596988934326">
                        <joint name="back_right_slipping_11_joint" type="hinge" pos="0 0 0" axis="-0.017203193977868635 0.0435 -0.01720319397786861" damping="0.1" limited="false" actuatorfrclimited="false"/>
                        <inertial pos="0 0 0" quat="0.711549 0.711549 0 0 " mass="0.001" diaginertia="0.00001 0.00001 0.00001" />
                        <geom size="0.08" quat="1 0 0 0" type="sphere" rgba="0.2 0.2 0.2 1" contype="1" conaffinity="0" group="3"/>
                    </body>
                </body>

                <body name="back_left_wheel_intermediate_link" pos="-0.2225 0.2045 0">
                    <inertial pos="0 0 0" quat="0.707107 0 0 0.707107" mass="6.5" diaginertia="0.0524193 0.0303095 0.0303095" />
                    <joint name="back_left_wheel_rolling_joint" pos="0 0 0" axis="0 1 0" />
                    <geom size="0.120 0.0435" quat="0.707107 0.707107 0 0" type="cylinder" rgba="0.2 0.2 0.2 0.5" contype="1" conaffinity="0" group="3"/>
                    <geom type="mesh" mesh="summit_xls_omni_wheel_2" contype="0" conaffinity="0" group="2" rgba="0.2 0.2 0.2 1"/>


                    <body name="back_left_roller_0_link" pos="0.04385159698893431 0.0 0.011749999999999998">
                        <joint name="back_left_slipping_0_joint" type="hinge" pos="0 0 0" axis="-0.006296806022131382 0.0435 0.023499999999999997" damping="0.1" limited="false" actuatorfrclimited="false"/>
                        <inertial pos="0 0 0" quat="0.711549 0.711549 0 0 " mass="0.001" diaginertia="0.00001 0.00001 0.00001" />
                        <geom size="0.08" quat="1 0 0 0" type="sphere" rgba="0.2 0.2 0.2 1" contype="1" conaffinity="0" group="3"/>
                    </body>

                    <body name="back_left_roller_1_link" pos="0.03210159698893431 0.0 0.032101596988934306">
                        <joint name="back_left_slipping_1_joint" type="hinge" pos="0 0 0" axis="-0.01720319397786861 0.0435 0.017203193977868615" damping="0.1" limited="false" actuatorfrclimited="false"/>
                        <inertial pos="0 0 0" quat="0.711549 0.711549 0 0 " mass="0.001" diaginertia="0.00001 0.00001 0.00001" />
                        <geom size="0.08" quat="1 0 0 0" type="sphere" rgba="0.2 0.2 0.2 1" contype="1" conaffinity="0" group="3"/>
                    </body>

                    <body name="back_left_roller_2_link" pos="0.011750000000000005 0.0 0.0438515969889343">
                        <joint name="back_left_slipping_2_joint" type="hinge" pos="0 0 0" axis="-0.023500000000000004 0.0435 0.006296806022131389" damping="0.1" limited="false" actuatorfrclimited="false"/>
                        <inertial pos="0 0 0" quat="0.711549 0.711549 0 0 " mass="0.001" diaginertia="0.00001 0.00001 0.00001" />
                        <geom size="0.08" quat="1 0 0 0" type="sphere" rgba="0.2 0.2 0.2 1" contype="1" conaffinity="0" group="3"/>
                    </body>

                    <body name="back_left_roller_3_link" pos="-0.011749999999999993 0.0 0.04385159698893431">
                        <joint name="back_left_slipping_3_joint" type="hinge" pos="0 0 0" axis="-0.023499999999999993 0.0435 -0.006296806022131382" damping="0.1" limited="false" actuatorfrclimited="false"/>
                        <inertial pos="0 0 0" quat="0.711549 0.711549 0 0 " mass="0.001" diaginertia="0.00001 0.00001 0.00001" />
                        <geom size="0.08" quat="1 0 0 0" type="sphere" rgba="0.2 0.2 0.2 1" contype="1" conaffinity="0" group="3"/>
                    </body>

                    <body name="back_left_roller_4_link" pos="-0.0321015969889343 0.0 0.03210159698893432">
                        <joint name="back_left_slipping_4_joint" type="hinge" pos="0 0 0" axis="-0.01720319397786862 0.0435 -0.0172031939778686" damping="0.1" limited="false" actuatorfrclimited="false"/>
                        <inertial pos="0 0 0" quat="0.711549 0.711549 0 0 " mass="0.001" diaginertia="0.00001 0.00001 0.00001" />
                        <geom size="0.08" quat="1 0 0 0" type="sphere" rgba="0.2 0.2 0.2 1" contype="1" conaffinity="0" group="3"/>
                    </body>

                    <body name="back_left_roller_5_link" pos="-0.0438515969889343 0.0 0.011750000000000012">
                        <joint name="back_left_slipping_5_joint" type="hinge" pos="0 0 0" axis="-0.006296806022131389 0.0435 -0.02350000000000001" damping="0.1" limited="false" actuatorfrclimited="false"/>
                        <inertial pos="0 0 0" quat="0.711549 0.711549 0 0 " mass="0.001" diaginertia="0.00001 0.00001 0.00001" />
                        <geom size="0.08" quat="1 0 0 0" type="sphere" rgba="0.2 0.2 0.2 1" contype="1" conaffinity="0" group="3"/>
                    </body>

                    <body name="back_left_roller_6_link" pos="-0.043851596988934316 0.0 -0.011749999999999991">
                        <joint name="back_left_slipping_6_joint" type="hinge" pos="0 0 0" axis="0.006296806022131375 0.0435 -0.023499999999999993" damping="0.1" limited="false" actuatorfrclimited="false"/>
                        <inertial pos="0 0 0" quat="0.711549 0.711549 0 0 " mass="0.001" diaginertia="0.00001 0.00001 0.00001" />
                        <geom size="0.08" quat="1 0 0 0" type="sphere" rgba="0.2 0.2 0.2 1" contype="1" conaffinity="0" group="3"/>
                    </body>

                    <body name="back_left_roller_7_link" pos="-0.03210159698893432 0.0 -0.03210159698893429">
                        <joint name="back_left_slipping_7_joint" type="hinge" pos="0 0 0" axis="0.017203193977868604 0.0435 -0.017203193977868618" damping="0.1" limited="false" actuatorfrclimited="false"/>
                        <inertial pos="0 0 0" quat="0.711549 0.711549 0 0 " mass="0.001" diaginertia="0.00001 0.00001 0.00001" />
                        <geom size="0.08" quat="1 0 0 0" type="sphere" rgba="0.2 0.2 0.2 1" contype="1" conaffinity="0" group="3"/>
                    </body>

                    <body name="back_left_roller_8_link" pos="-0.011750000000000014 0.0 -0.0438515969889343">
                        <joint name="back_left_slipping_8_joint" type="hinge" pos="0 0 0" axis="0.023500000000000014 0.0435 -0.006296806022131396" damping="0.1" limited="false" actuatorfrclimited="false"/>
                        <inertial pos="0 0 0" quat="0.711549 0.711549 0 0 " mass="0.001" diaginertia="0.00001 0.00001 0.00001" />
                        <geom size="0.08" quat="1 0 0 0" type="sphere" rgba="0.2 0.2 0.2 1" contype="1" conaffinity="0" group="3"/>
                    </body>

                    <body name="back_left_roller_9_link" pos="0.01174999999999998 0.0 -0.043851596988934316">
                        <joint name="back_left_slipping_9_joint" type="hinge" pos="0 0 0" axis="0.023499999999999976 0.0435 0.006296806022131368" damping="0.1" limited="false" actuatorfrclimited="false"/>
                        <inertial pos="0 0 0" quat="0.711549 0.711549 0 0 " mass="0.001" diaginertia="0.00001 0.00001 0.00001" />
                        <geom size="0.08" quat="1 0 0 0" type="sphere" rgba="0.2 0.2 0.2 1" contype="1" conaffinity="0" group="3"/>
                    </body>

                    <body name="back_left_roller_10_link" pos="0.032101596988934285 0.0 -0.032101596988934326">
                        <joint name="back_left_slipping_10_joint" type="hinge" pos="0 0 0" axis="0.017203193977868635 0.0435 0.01720319397786861" damping="0.1" limited="false" actuatorfrclimited="false"/>
                        <inertial pos="0 0 0" quat="0.711549 0.711549 0 0 " mass="0.001" diaginertia="0.00001 0.00001 0.00001" />
                        <geom size="0.08" quat="1 0 0 0" type="sphere" rgba="0.2 0.2 0.2 1" contype="1" conaffinity="0" group="3"/>
                    </body>

                    <body name="back_left_roller_11_link" pos="0.0438515969889343 0.0 -0.01175000000000001">
                        <joint name="back_left_slipping_11_joint" type="hinge" pos="0 0 0" axis="0.006296806022131396 0.0435 0.02350000000000002" damping="0.1" limited="false" actuatorfrclimited="false"/>
                        <inertial pos="0 0 0" quat="0.711549 0.711549 0 0 " mass="0.001" diaginertia="0.00001 0.00001 0.00001" />
                        <geom size="0.08" quat="1 0 0 0" type="sphere" rgba="0.2 0.2 0.2 1" contype="1" conaffinity="0" group="3"/>
                    </body>
                </body>

                <!-- ARM MOUNTED ON TOP OF MOBILE BASE -->
                <!-- Position the arm base on top of the robot chassis -->
                <body name="Arm" pos="0.0 0.0 0.158566">
                    <inertial pos="0 0 0.2925" quat="0.9234 0 0 0.383838" mass="1" diaginertia="0.511811 0.471811 0.0770056"/>
                    <joint name="BaseJoint" pos="0 0 0" axis="0 0 1" range="-3.14159 3.14159"  limited="false" />
                    <geom type="mesh" rgba="0.75 0.75 0.75 1" mesh="Column_Rotation" />
                    <geom type="cylinder" size="0.22 0.04" pos="0 0 0.02" quat="1 0 0 0" rgba="0 1 0 0" contype="1" conaffinity="1"/>
                    <geom type="mesh" rgba="0.75 0.75 0.75 1" mesh="Column_Left"  />
                    <geom type="mesh" rgba="0.75 0.75 0.75 1" mesh="Column_Right" />
                    <body name="camera_pov" pos="-1 0 1.8" euler="0 -0.785398 -1.57">
                        <!-- <geom type="cylinder" size="0.01 0.02"/> -->
                        <camera name="pov" fovy="60"/>
                    </body>
                    <body name="Bearing_Column_Left" pos="0.1 -0.08 0.1">
                        <inertial pos="0 0 0" quat="0.707107 0 0 0.707107" mass="0.1" diaginertia="0.000125 6.58333e-05 6.58333e-05"/>
                        <joint name="ColumnLeftBearingJoint" pos="0 0 0" axis="0 0 1" type="slide" range="0 1.1" stiffness="50000" damping="1000"/>
                        <geom pos="-0.1 0.08 -0.5" quat="1 0 0 0" type="mesh" rgba="0.75 0.75 0.75 1" mesh="Bearing_Column_Left"/>
                        <body name="Rotation_Link_Left">
                            <inertial pos="0 0 0" quat="0.707107 0 0 0.707107" mass="0.05" diaginertia="8.33333e-06 7.08333e-06 2.08333e-06"/>
                            <joint name="RotationLeftJoint" pos="0 0 0" axis="0 1 0" stiffness="100"/>
                            <geom pos="-0.1 0.08 -0.5" quat="1 0 0 0" type="mesh" rgba="0.75 0.75 0.75 1" mesh="Left_Rotation" contype="0" conaffinity="0"/>
                            <body name="Arm_Left" pos="-0.4 0.02 0">
                                <inertial pos="0 0 0" euler="0 1.57 0" mass="0.7" diaginertia="0.0584267 0.0583567 0.000116667"/>
                                <joint name="ArmLeftJoint" pos="0 0 0" axis="1 0 0" type="slide" range="0 0.7"  stiffness="50000" damping="1000"/>
                                <geom pos="-0.2 0.06 -0.5" quat="1 0 0 0" type="mesh" rgba="0.75 0.75 0.75 1" mesh="Arm_Left" contype="0" conaffinity="0" />
                                <geom type="box" size="0.555 0.02 0.04" pos="-0.05 0.005 0" quat="1 0 0 0" rgba="0 1 0 0" contype="1" conaffinity="1"/>
                                
                                <body name="Hand_Bearing" pos="0.475 0.01 0">
                                    <inertial pos="0.0138889 0.05 0" quat="0.5 0.5 -0.5 0.5" mass="0.45" diaginertia="0.000358507 0.000276042 0.00022309"/>
                                    <joint name="HandBearingJoint" pos="0 0 0" axis="0 1 0"  damping="1"/>
                                    <geom pos="-0.325 0.05 -0.5" quat="1 0 0 0" type="mesh" rgba="0.75 0.75 0.75 1" mesh="Hand_Bearing"/>
                                    <geom size="0.025 0.025" pos="0.025 0.05 0" quat="0.707107 0 0.707107 0" type="cylinder" rgba="0.75 0.75 0.75 1"/>
                                    <body name="Contact_Cylinder" pos="0 0.1 0">
                                        <inertial pos="0 0 0" quat="0.707107 0 0 0.707107" mass="0.001" diaginertia="3.125e-07 1.56333e-07 1.56333e-07"/>
                                        <joint name="ContactCylinderJoint" pos="0 0 0" axis="0 1 0"  damping="5.0"/>
                                        <!-- <geom pos="-0.325 -0.05 -0.5" quat="1 0 0 0" type="mesh" rgba="0.75 0.75 0.75 1" mesh="Contact_Cylinder"/> -->
                                        <site name="cyl_weld_site" pos="0 0.01 0" size="0.005" type="sphere" material="connection_marker_green"/>
                                    </body>
                                    <body name="Gripper_Link1" pos="0.05 0.05 0" quat="0.707107 0 0.707107 0">
                                        <site name="attachment_site" size="0.01" rgba="1 0 0 1" group="1"/>
                                        <inertial pos="0 0 0" quat="0.5 0.5 -0.5 0.5" mass="0.05" diaginertia="2.25e-05 1.5e-05 1.5e-05"/>
                                        <joint name="gripper_z_rotation" pos="0 0 0" axis="0 0 1" range="-3.14159 3.14159"  stiffness="200" damping="30"/>
                                        <geom size="0.03 0.015" type="cylinder" material="robotiq_chrome"/>
                                        <body name="Gripper_Link2" pos="0 0 0.015">
                                            <inertial pos="0 0 0" mass="0.05" diaginertia="5.33333e-05 5.33333e-05 5.33333e-05"/>
                                            <joint name="gripper_y_rotation" pos="0 0 0" axis="0 1 0" range="-1.5708 1.5708"  stiffness="200" damping="30"/>
                                            <geom size="0.04" material="robotiq_black"/>
                                            <body name="Gripper_Link3">
                                                <inertial pos="0 0 0" mass="0.05" diaginertia="5.33333e-05 5.33333e-05 5.33333e-05"/>
                                                <joint name="gripper_x_rotation" pos="0 0 0" axis="1 0 0" range="-1.5708 1.5708"  stiffness="200" damping="30"/>
                                                <geom pos="0 0 0.04" quat="0.707107 0.707107 0 0" type="mesh" material="robotiq_black" mesh="palm_real"/>
                                                <geom pos="0 0 0.04" quat="0.707107 0.707107 0 0" type="mesh" material="robotiq_chrome" mesh="palm_atc"/>
                                                <geom pos="0.0455159 0 0.0814" quat="0.500199 0.500199 -0.499801 0.499801" type="mesh" mesh="link_0_real" material="robotiq_black" friction="5 5 5" solimp="0.9 0.95 0.001 0.5 2" solref="0.001 1" solmix="3" priority="1" condim="6"/>
                                                <body name="finger_c_link_0" pos="-0.0455 -0.036 0.0614" quat="-0.499803 0.499799 0.500197 0.500201">
                                                    <inertial pos="0 0 0" euler="0 0 0" mass="0.1" diaginertia="0.000015 0.000015 0.000015"/>
                                                    <joint name="palm_finger_c_joint" pos="0 0 0" axis="0 1 0" range="-0.1784 0.192" stiffness="10" damping="5"/>
                                                    <geom pos="0.02 0 0" quat="1 0 0 0" type="mesh" mesh="link_0_real" material="robotiq_black" friction="5 5 5" solimp="0.9 0.95 0.001 0.5 2" solref="0.001 1" solmix="3" priority="1" condim="6" />
                                                    <body name="finger_c_link_1" pos="0.02 0 0">
                                                        <inertial pos="0 0 0" euler="0 0 0" mass="0.1" diaginertia="0.000015 0.000015 0.000015"/>
                                                        <joint name="finger_c_joint_1" pos="0 0 0" axis="0 0 1" range="0.0495 1.2218" stiffness="10" damping="5"/>
                                                        <geom pos="0.05 -0.028 0" quat="0.96639 0 0 -0.257081" type="mesh" mesh="link_1_real" material="robotiq_black" friction="5 5 5" solimp="0.9 0.95 0.001 0.5 2" solref="0.001 1" solmix="3" priority="1" condim="6"/>
                                                        <geom class="pad_box1" size="0.031 0.005 0.013" pos="0.035 -0.01  0" euler=" 0 -0 -0.55" rgba=" 0 0 0 0"/>
                                                        <geom class="pad_box2" size="0.031 0.005 0.013" pos="0.035 -0.012 0" euler=" 0 -0 -0.55" rgba=" 0 0 0 0"/>
                                                        <body name="finger_c_link_2" pos="0.05 -0.028 0" quat="0.96639 0 0 -0.257081">
                                                            <inertial pos="0 0 0" euler="0 0 0" mass="0.1" diaginertia="0.000015 0.000015 0.000015"/>
                                                            <joint name="finger_c_joint_2" pos="0 0 0" axis="0 0 1" range="0 1.5708" stiffness="10" damping="5"/>
                                                            <geom pos="0.039 0 0.0075" quat="1 0 0 0" type="mesh" mesh="link_2_real" material="robotiq_black" friction="5 5 5" solimp="0.9 0.95 0.001 0.5 2" solref="0.001 1" solmix="3" priority="1" condim="6"/>
                                                            <geom class="pad_box1" size="0.022 0.005 0.013" pos="0.025 0.007  0" euler=" 0 -0 0" rgba=" 0 0 0 0"/>
                                                            <geom class="pad_box2" size="0.022 0.005 0.013" pos="0.025 0.0072 0" euler=" 0 -0 0" rgba=" 0 0 0 0"/>
                                                            <body name="finger_c_link_3" pos="0.039 0 0">
                                                                <inertial pos="0 0 0" quat="0.614353 0.390886 -0.585309 0.35664" mass="0.05" diaginertia="0.00163315 0.00136097 0.000726883"/>
                                                                <joint name="finger_c_joint_3" pos="0 0 0" axis="0 0 1" range="-1.2217 -0.0523" stiffness="10" damping="5"/>
                                                                <geom quat="0.96639 0 0 0.257081" type="mesh" material="robotiq_black" mesh="link_3_real" friction="5 5 5" solimp="0.9 0.95 0.001 0.5 2" solref="0.001 1" solmix="3" priority="1" condim="6"/>
                                                                <geom class="pad_box1" size="0.02 0.005 0.013" pos="0.01 0.0150  0"  euler=" 0 -0 0.5" rgba=" 0 0 0 0"/>
                                                                <geom class="pad_box2" size="0.02 0.005 0.013" pos="0.01 0.0154 0"  euler=" 0 -0 0.5" rgba=" 0 0 0 0"/>
                                                                <geom class="pad_box2" size="0.02 0.005 0.013" pos="0.01 0.0160 0"  euler=" 0 -0 0.5" rgba=" 0 0 0 0"/>
                                                            </body>
                                                        </body>
                                                    </body>
                                                </body>
                                                <body name="finger_b_link_0" pos="-0.0455 0.036 0.0614" quat="-0.499803 0.499799 0.500197 0.500201">
                                                    <inertial pos="0 0 0" euler="0 0 0" mass="0.1" diaginertia="0.000015 0.000015 0.000015"/>
                                                    <joint name="palm_finger_b_joint" pos="0 0 0" axis="0 1 0" range="-0.192 0.1784" stiffness="10" damping="5"/>
                                                    <geom pos="0.02 0 0" quat="1 0 0 0" type="mesh" mesh="link_0_real" material="robotiq_black" friction="5 5 5" solimp="0.9 0.95 0.001 0.5 2" solref="0.004 1" solmix="3" priority="1" condim="6" />
                                                    <body name="finger_b_link_1" pos="0.02 0 0">
                                                        <inertial pos="0 0 0" euler="0 0 0" mass="0.1" diaginertia="0.000015 0.000015 0.000015"/>
                                                        <joint name="finger_b_joint_1" pos="0 0 0" axis="0 0 1" range="0.0495 1.2218" stiffness="10" damping="5"/>
                                                        <geom pos="0.05 -0.028 0" quat="0.96639 0 0 -0.257081" type="mesh" mesh="link_1_real" material="robotiq_black" friction="5 5 5" solimp="0.9 0.95 0.001 0.5 2" solref="0.004 1" solmix="3" priority="1" condim="6"/>
                                                        <geom class="pad_box1" size="0.031 0.005 0.013" pos="0.035 -0.01  0" euler=" 0 -0 -0.55" rgba=" 0 0 0 0"/>
                                                        <geom class="pad_box2" size="0.031 0.005 0.013" pos="0.035 -0.012 0" euler=" 0 -0 -0.55" rgba=" 0 0 0 0"/>
                                                        <body name="finger_b_link_2" pos="0.05 -0.028 0" quat="0.96639 0 0 -0.257081">
                                                            <inertial pos="0 0 0" euler="0 0 0" mass="0.1" diaginertia="0.000015 0.000015 0.000015"/>
                                                            <joint name="finger_b_joint_2" pos="0 0 0" axis="0 0 1" range="0 1.5708" stiffness="10" damping="5"/>
                                                            <geom pos="0.039 0 0.0075" quat="1 0 0 0" type="mesh" mesh="link_2_real" material="robotiq_black" friction="5 5 5" solimp="0.9 0.95 0.001 0.5 2" solref="0.004 1" solmix="3" priority="1" condim="6"/>
                                                            <geom class="pad_box1" size="0.022 0.005 0.013" pos="0.025 0.007  0" euler=" 0 -0 0" rgba=" 0 0 0 0"/>
                                                            <geom class="pad_box2" size="0.022 0.005 0.013" pos="0.025 0.0072 0" euler=" 0 -0 0" rgba=" 0 0 0 0"/>
                                                            <body name="finger_b_link_3" pos="0.039 0 0">
                                                                <inertial pos="0 0 0" quat="0.614353 0.390886 -0.585309 0.35664" mass="0.05" diaginertia="0.00163315 0.00136097 0.000726883"/>
                                                                <joint name="finger_b_joint_3" pos="0 0 0" axis="0 0 1" range="-1.2217 -0.0523" stiffness="10" damping="5"/>
                                                                <geom quat="0.96639 0 0 0.257081" type="mesh" material="robotiq_black" mesh="link_3_real" friction="5 5 5" solimp="0.9 0.95 0.001 0.5 2" solref="0.004 1" solmix="3" priority="1" condim="6"/>
                                                                <geom class="pad_box1" size="0.02 0.005 0.013" pos="0.01 0.0150  0"  euler=" 0 -0 0.5" rgba=" 0 0 0 0"/>
                                                                <geom class="pad_box2" size="0.02 0.005 0.013" pos="0.01 0.0156 0" euler=" 0 -0 0.5" rgba=" 0 0 0 0"/>
                                                                <geom class="pad_box2" size="0.02 0.005 0.013" pos="0.01 0.0160 0" euler=" 0 -0 0.5" rgba=" 0 0 0 0"/>
                                                            </body>
                                                        </body>
                                                    </body>
                                                </body>
                                                <body name="finger_a_link_1" pos="0.0455159 0 0.0814" quat="0.500199 0.500199 -0.499801 0.499801">
                                                    <inertial pos="0 0 0" euler="0 0 0" mass="0.1" diaginertia="0.000015 0.000015 0.000015"/>
                                                    <joint name="finger_a_joint_1" pos="0 0 0" axis="0 0 1" range="0.0495 1.2218" stiffness="10" damping="5"/>
                                                    <geom pos="0.05 -0.028 0" quat="0.96639 0 0 -0.257081" type="mesh" mesh="link_1_real" material="robotiq_black" friction="5 5 5" solimp="0.9 0.95 0.001 0.5 2" solref="0.004 1" solmix="3" priority="1" condim="6"/>
                                                    <geom class="pad_box1" size="0.031 0.005 0.015" pos="0.035 -0.01  0" euler=" 0 -0 -0.55" rgba=" 0 0 0 0"/>
                                                    <geom class="pad_box2" size="0.031 0.005 0.015" pos="0.035 -0.015 0" euler=" 0 -0 -0.55" rgba=" 0 0 0 0"/>
                                                    <body name="finger_a_link_2" pos="0.05 -0.028 0" quat="0.96639 0 0 -0.257081">
                                                        <inertial pos="0 0 0" euler="0 0 0" mass="0.1" diaginertia="0.000015 0.000015 0.000015"/>
                                                        <joint name="finger_a_joint_2" pos="0 0 0" axis="0 0 1" range="0 1.5708" stiffness="10" damping="5"/>
                                                        <geom pos="0.039 0 0.0075" quat="1 0 0 0" type="mesh" mesh="link_2_real" material="robotiq_black" friction="5 5 5" solimp="0.9 0.95 0.001 0.5 2" solref="0.004 1" solmix="3" priority="1" condim="6"/>
                                                        <geom class="pad_box1" size="0.022 0.005 0.015" pos="0.025 0.007  0" euler=" 0 -0 0" rgba=" 0 0 0 0"/>
                                                        <geom class="pad_box2" size="0.022 0.005 0.015" pos="0.025 0.0072 0" euler=" 0 -0 0" rgba=" 0 0 0 0"/>
                                                        <body name="finger_a_link_3" pos="0.039 0 0">
                                                            <inertial pos="0 0 0" quat="0.614353 0.390886 -0.585309 0.35664" mass="0.05" diaginertia="0.00163315 0.00136097 0.000726883"/>
                                                            <joint name="finger_a_joint_3" pos="0 0 0" axis="0 0 1" range="-1.2217 -0.0523" stiffness="10" damping="5"/>
                                                            <geom quat="0.96639 0 0 0.257081" type="mesh" material="robotiq_black" mesh="link_3_real" friction="5 5 5" solimp="0.9 0.95 0.001 0.5 2" solref="0.001 1" solmix="3" priority="1" condim="6"/>
                                                            <geom class="pad_box1" size="0.02 0.005 0.013" pos="0.01 0.0150  0" euler=" 0 -0 0.5" rgba=" 0 0 0 0"/>
                                                            <geom class="pad_box2" size="0.02 0.005 0.013" pos="0.01 0.0156 0" euler=" 0 -0 0.5" rgba=" 0 0 0 0"/>
                                                            <geom class="pad_box2" size="0.02 0.005 0.013" pos="0.01 0.0160 0" euler=" 0 -0 0.5" rgba=" 0 0 0 0"/>
                                                        </body>
                                                    </body>
                                                </body>
                                            </body>
                                        </body>
                                    </body>
                                </body>
                            </body>
                        </body>
                    </body>
                    <body name="Bearing_Column_Right" pos="-0.1 0.08 0.1">
                        <inertial pos="0 0 0" quat="0.707107 0 0 0.707107" mass="0.1" diaginertia="0.000125 6.58333e-05 6.58333e-05"/>
                        <joint name="ColumnRightBearingJoint" pos="0 0 0" axis="0 0 1" type="slide" range="0 1.1"  stiffness="50000" damping="1000"/>
                        <geom pos="0.1 -0.08 -0.5" quat="1 0 0 0" type="mesh" rgba="0.75 0.75 0.75 1" mesh="Bearing_Column_Right" contype="0" conaffinity="0"/>
                        <body name="Rotation_Link_Right">
                            <inertial pos="0 0 0" quat="0.707107 0 0 0.707107" mass="0.05" diaginertia="8.33333e-06 7.08333e-06 2.08333e-06"/>
                            <joint name="RotationRightJoint" pos="0 0 0" axis="0 1 0" stiffness="100"/>
                            <geom pos="0.1 -0.08 -0.5" quat="1 0 0 0" type="mesh" rgba="0.75 0.75 0.75 1" mesh="Right_Rotation" contype="0" conaffinity="0"/>
                            <body name="Arm_Right" pos="-0.4 -0.02 0">
                                <inertial pos="0.2 0 0" euler="0 1.57 0" mass="0.7" diaginertia="0.0584267 0.0583567 0.000116667"/>
                                <joint name="ArmRightJoint" pos="0 0 0" axis="1 0 0" type="slide" range="0 0.7"  stiffness="50000" damping="1000"/>
                                <geom pos="0 -0.06 -0.5" quat="1 0 0 0" type="mesh" rgba="0.75 0.75 0.75 1" mesh="Arm_Right" contype="0" conaffinity="0"/>
                                <geom type="box" size="0.555 0.02 0.04" pos="0.15 -0.005 0" quat="1 0 0 0" rgba="0 1 0 0" contype="1" conaffinity="1"/>
                                <site name="arm_weld_site" pos="0.685 0.0 0.0" size="0.005" type="sphere" material="connection_marker_blue"/>
                            </body>
                        </body>
                    </body>
                </body>

            </body>
        </body>

</mujocoinclude>
